Workbook

Sheet 批量打印
A1: 光缆段名称 | B1: 距离(米) | C1: 芯数 | D1: 年月 | E1: 波长 | F1: 平均衰耗 | G1: 是否成端 | H1: 事件距离 | I1: 假纤 | J1: 光缆标号
A2: =IF(数据!B2=0,"",数据!B2) -> 马嘶工业园光交至正威华东基站 | B2: =IF(数据!B2=0,"",数据!D2) -> 109.4 | C2: =IF(数据!B2=0,"",数据!F2&"-"&数据!G2) -> 1-24 | D2: =IF(数据!B2=0,"",数据!I2&数据!$I$1&数据!J2&数据!$J$1&数据!K2&数据!$K$1&数据!L2&数据!$L$1&数据!M2&数据!$M$1) -> 2022年11月14日14时51分 | E2: =IF(数据!B2=0,"",数据!N2) -> 1550 | F2: =IF(数据!B2=0,"",数据!O2) -> 0.19 | G2: =IF(数据!B2=0,"",数据!P2) -> 是
A3: =IF(数据!B3=0,"",数据!B3) -> 南浔世友地板基站至南浔新桥南堍光交 | B3: =IF(数据!B3=0,"",数据!D3) -> 1171.4 | C3: =IF(数据!B3=0,"",数据!F3&"-"&数据!G3) -> 1-24 | D3: =IF(数据!B3=0,"",数据!I3&数据!$I$1&数据!J3&数据!$J$1&数据!K3&数据!$K$1&数据!L3&数据!$L$1&数据!M3&数据!$M$1) -> 2022年11月15日8时36分 | E3: =IF(数据!B3=0,"",数据!N3) -> 1550 | F3: =IF(数据!B3=0,"",数据!O3) -> 0.19 | G3: =IF(数据!B3=0,"",数据!P3) -> 是
A4: =IF(数据!B4=0,"",数据!B4) -> 方家港基站至浔织路浔北路光交 | B4: =IF(数据!B4=0,"",数据!D4) -> 1354.1 | C4: =IF(数据!B4=0,"",数据!F4&"-"&数据!G4) -> 1-24 | D4: =IF(数据!B4=0,"",数据!I4&数据!$I$1&数据!J4&数据!$J$1&数据!K4&数据!$K$1&数据!L4&数据!$L$1&数据!M4&数据!$M$1) -> 2022年11月13日12时30分 | E4: =IF(数据!B4=0,"",数据!N4) -> 1550 | F4: =IF(数据!B4=0,"",数据!O4) -> 0.19 | G4: =IF(数据!B4=0,"",数据!P4) -> 是
A5: =IF(数据!B5=0,"",数据!B5) -> 朱家田新基站至铁塔菱湖南鱼鳌基站 | B5: =IF(数据!B5=0,"",数据!D5) -> 1607.5 | C5: =IF(数据!B5=0,"",数据!F5&"-"&数据!G5) -> 1-24 | D5: =IF(数据!B5=0,"",数据!I5&数据!$I$1&数据!J5&数据!$J$1&数据!K5&数据!$K$1&数据!L5&数据!$L$1&数据!M5&数据!$M$1) -> 2022年11月17日15时20分 | E5: =IF(数据!B5=0,"",数据!N5) -> 1550 | F5: =IF(数据!B5=0,"",数据!O5) -> 0.19 | G5: =IF(数据!B5=0,"",数据!P5) -> 是
A6: =IF(数据!B6=0,"",数据!B6) -> 花林农兴村基站至练市乌林浜基站 | B6: =IF(数据!B6=0,"",数据!D6) -> 1133.2 | C6: =IF(数据!B6=0,"",数据!F6&"-"&数据!G6) -> 1-24 | D6: =IF(数据!B6=0,"",数据!I6&数据!$I$1&数据!J6&数据!$J$1&数据!K6&数据!$K$1&数据!L6&数据!$L$1&数据!M6&数据!$M$1) -> 2022年11月19日9时44分 | E6: =IF(数据!B6=0,"",数据!N6) -> 1550 | F6: =IF(数据!B6=0,"",数据!O6) -> 0.19 | G6: =IF(数据!B6=0,"",数据!P6) -> 是
A7: =IF(数据!B7=0,"",数据!B7) -> 嘉业路南光交至开元名都度假区20幢楼顶搬迁基站 | B7: =IF(数据!B7=0,"",数据!D7) -> 1017.9 | C7: =IF(数据!B7=0,"",数据!F7&"-"&数据!G7) -> 1-24 | D7: =IF(数据!B7=0,"",数据!I7&数据!$I$1&数据!J7&数据!$J$1&数据!K7&数据!$K$1&数据!L7&数据!$L$1&数据!M7&数据!$M$1) -> 2022年11月15日13时11分 | E7: =IF(数据!B7=0,"",数据!N7) -> 1550 | F7: =IF(数据!B7=0,"",数据!O7) -> 0.19 | G7: =IF(数据!B7=0,"",数据!P7) -> 是
A8: =IF(数据!B8=0,"",数据!B8) -> 骏马木业基站至引下大象酒店地下室机房 | B8: =IF(数据!B8=0,"",数据!D8) -> 1760.4 | C8: =IF(数据!B8=0,"",数据!F8&"-"&数据!G8) -> 1-48 | D8: =IF(数据!B8=0,"",数据!I8&数据!$I$1&数据!J8&数据!$J$1&数据!K8&数据!$K$1&数据!L8&数据!$L$1&数据!M8&数据!$M$1) -> 2022年11月12日16时19分 | E8: =IF(数据!B8=0,"",数据!N8) -> 1550 | F8: =IF(数据!B8=0,"",数据!O8) -> 0.19 | G8: =IF(数据!B8=0,"",数据!P8) -> 是
A9: =IF(数据!B9=0,"",数据!B9) -> 菱湖竹墩岔口光交至菱湖前丘家苑基站 | B9: =IF(数据!B9=0,"",数据!D9) -> 1460.5 | C9: =IF(数据!B9=0,"",数据!F9&"-"&数据!G9) -> 1-24 | D9: =IF(数据!B9=0,"",数据!I9&数据!$I$1&数据!J9&数据!$J$1&数据!K9&数据!$K$1&数据!L9&数据!$L$1&数据!M9&数据!$M$1) -> 2022年11月17日8时30分 | E9: =IF(数据!B9=0,"",数据!N9) -> 1550 | F9: =IF(数据!B9=0,"",数据!O9) -> 0.19 | G9: =IF(数据!B9=0,"",数据!P9) -> 是
A10: =IF(数据!B10=0,"",数据!B10) -> 和孚毛东港基站至湖盐公路星光农机北光交 | B10: =IF(数据!B10=0,"",数据!D10) -> 2304.2 | C10: =IF(数据!B10=0,"",数据!F10&"-"&数据!G10) -> 1-24 | D10: =IF(数据!B10=0,"",数据!I10&数据!$I$1&数据!J10&数据!$J$1&数据!K10&数据!$K$1&数据!L10&数据!$L$1&数据!M10&数据!$M$1) -> 2022年11月14日16时28分 | E10: =IF(数据!B10=0,"",数据!N10) -> 1550 | F10: =IF(数据!B10=0,"",数据!O10) -> 0.19 | G10: =IF(数据!B10=0,"",数据!P10) -> 是
A11: =IF(数据!B11=0,"",数据!B11) -> 江蒋漾新村基站至西城路年丰路光交 | B11: =IF(数据!B11=0,"",数据!D11) -> 556.2 | C11: =IF(数据!B11=0,"",数据!F11&"-"&数据!G11) -> 1-24 | D11: =IF(数据!B11=0,"",数据!I11&数据!$I$1&数据!J11&数据!$J$1&数据!K11&数据!$K$1&数据!L11&数据!$L$1&数据!M11&数据!$M$1) -> 2022年11月19日14时28分 | E11: =IF(数据!B11=0,"",数据!N11) -> 1550 | F11: =IF(数据!B11=0,"",数据!O11) -> 0.19 | G11: =IF(数据!B11=0,"",数据!P11) -> 是
A12: =IF(数据!B12=0,"",数据!B12) -> 阳光大道与外环南路光交至玉麟府无线机房 | B12: =IF(数据!B12=0,"",数据!D12) -> 214 | C12: =IF(数据!B12=0,"",数据!F12&"-"&数据!G12) -> 1-24 | D12: =IF(数据!B12=0,"",数据!I12&数据!$I$1&数据!J12&数据!$J$1&数据!K12&数据!$K$1&数据!L12&数据!$L$1&数据!M12&数据!$M$1) -> 2022年11月16日13时10分 | E12: =IF(数据!B12=0,"",数据!N12) -> 1550 | F12: =IF(数据!B12=0,"",数据!O12) -> 0.19 | G12: =IF(数据!B12=0,"",数据!P12) -> 是
A13: =IF(数据!B13=0,"",数据!B13) -> 玉麟府无线机房至玉麟府有线机房 | B13: =IF(数据!B13=0,"",数据!D13) -> 38.5 | C13: =IF(数据!B13=0,"",数据!F13&"-"&数据!G13) -> 1-24 | D13: =IF(数据!B13=0,"",数据!I13&数据!$I$1&数据!J13&数据!$J$1&数据!K13&数据!$K$1&数据!L13&数据!$L$1&数据!M13&数据!$M$1) -> 2022年11月18日10时19分 | E13: =IF(数据!B13=0,"",数据!N13) -> 1550 | F13: =IF(数据!B13=0,"",数据!O13) -> 0.19 | G13: =IF(数据!B13=0,"",数据!P13) -> 是
... A104: =IF(数据!B104=0,"",数据!B104) | B104: =IF(数据!B104=0,"",数据!D104) | C104: =IF(数据!B104=0,"",数据!F104&"-"&数据!G104) | D104: =IF(数据!B104=0,"",数据!I104&数据!$I$1&数据!J104&数据!$J$1&数据!K104&数据!$K$1&数据!L104&数据!$L$1&数据!M104&数据!$M$1) | E104: =IF(数据!B104=0,"",数据!N104) | F104: =IF(数据!B104=0,"",数据!O104) | G104: =IF(数据!B104=0,"",数据!P104)
A105: =IF(数据!B115=0,"",数据!B115) | B105: =IF(数据!B115=0,"",数据!D115) | C105: =IF(数据!B115=0,"",数据!F115&"-"&数据!G115) | D105: =IF(数据!B115=0,"",数据!I115&数据!$I$1&数据!J115&数据!$J$1&数据!K115&数据!$K$1&数据!L115&数据!$L$1&数据!M115&数据!$M$1) | E105: =IF(数据!B115=0,"",数据!N115) | F105: =IF(数据!B115=0,"",数据!O115) | G105: =IF(数据!B115=0,"",数据!P115)
A106: =IF(数据!B116=0,"",数据!B116) | B106: =IF(数据!B116=0,"",数据!D116) | C106: =IF(数据!B116=0,"",数据!F116&"-"&数据!G116) | D106: =IF(数据!B116=0,"",数据!I116&数据!$I$1&数据!J116&数据!$J$1&数据!K116&数据!$K$1&数据!L116&数据!$L$1&数据!M116&数据!$M$1) | E106: =IF(数据!B116=0,"",数据!N116) | F106: =IF(数据!B116=0,"",数据!O116) | G106: =IF(数据!B116=0,"",数据!P116)
A107: =IF(数据!B117=0,"",数据!B117) | B107: =IF(数据!B117=0,"",数据!D117) | C107: =IF(数据!B117=0,"",数据!F117&"-"&数据!G117) | D107: =IF(数据!B117=0,"",数据!I117&数据!$I$1&数据!J117&数据!$J$1&数据!K117&数据!$K$1&数据!L117&数据!$L$1&数据!M117&数据!$M$1) | E107: =IF(数据!B117=0,"",数据!N117) | F107: =IF(数据!B117=0,"",数据!O117) | G107: =IF(数据!B117=0,"",数据!P117)
A108: =IF(数据!B118=0,"",数据!B118) | B108: =IF(数据!B118=0,"",数据!D118) | C108: =IF(数据!B118=0,"",数据!F118&"-"&数据!G118) | D108: =IF(数据!B118=0,"",数据!I118&数据!$I$1&数据!J118&数据!$J$1&数据!K118&数据!$K$1&数据!L118&数据!$L$1&数据!M118&数据!$M$1) | E108: =IF(数据!B118=0,"",数据!N118) | F108: =IF(数据!B118=0,"",数据!O118) | G108: =IF(数据!B118=0,"",数据!P118)
A109: =IF(数据!B119=0,"",数据!B119) | B109: =IF(数据!B119=0,"",数据!D119) | C109: =IF(数据!B119=0,"",数据!F119&"-"&数据!G119) | D109: =IF(数据!B119=0,"",数据!I119&数据!$I$1&数据!J119&数据!$J$1&数据!K119&数据!$K$1&数据!L119&数据!$L$1&数据!M119&数据!$M$1) | E109: =IF(数据!B119=0,"",数据!N119) | F109: =IF(数据!B119=0,"",数据!O119) | G109: =IF(数据!B119=0,"",数据!P119)
A110: =IF(数据!B120=0,"",数据!B120) | B110: =IF(数据!B120=0,"",数据!D120) | C110: =IF(数据!B120=0,"",数据!F120&"-"&数据!G120) | D110: =IF(数据!B120=0,"",数据!I120&数据!$I$1&数据!J120&数据!$J$1&数据!K120&数据!$K$1&数据!L120&数据!$L$1&数据!M120&数据!$M$1) | E110: =IF(数据!B120=0,"",数据!N120) | F110: =IF(数据!B120=0,"",数据!O120) | G110: =IF(数据!B120=0,"",数据!P120)
A111: =IF(数据!B121=0,"",数据!B121) | B111: =IF(数据!B121=0,"",数据!D121) | C111: =IF(数据!B121=0,"",数据!F121&"-"&数据!G121) | D111: =IF(数据!B121=0,"",数据!I121&数据!$I$1&数据!J121&数据!$J$1&数据!K121&数据!$K$1&数据!L121&数据!$L$1&数据!M121&数据!$M$1) | E111: =IF(数据!B121=0,"",数据!N121) | F111: =IF(数据!B121=0,"",数据!O121) | G111: =IF(数据!B121=0,"",数据!P121)
A112: =IF(数据!B122=0,"",数据!B122) | B112: =IF(数据!B122=0,"",数据!D122) | C112: =IF(数据!B122=0,"",数据!F122&"-"&数据!G122) | D112: =IF(数据!B122=0,"",数据!I122&数据!$I$1&数据!J122&数据!$J$1&数据!K122&数据!$K$1&数据!L122&数据!$L$1&数据!M122&数据!$M$1) | E112: =IF(数据!B122=0,"",数据!N122) | F112: =IF(数据!B122=0,"",数据!O122) | G112: =IF(数据!B122=0,"",数据!P122)
A113: =IF(数据!B123=0,"",数据!B123) | B113: =IF(数据!B123=0,"",数据!D123) | C113: =IF(数据!B123=0,"",数据!F123&"-"&数据!G123) | D113: =IF(数据!B123=0,"",数据!I123&数据!$I$1&数据!J123&数据!$J$1&数据!K123&数据!$K$1&数据!L123&数据!$L$1&数据!M123&数据!$M$1) | E113: =IF(数据!B123=0,"",数据!N123) | F113: =IF(数据!B123=0,"",数据!O123) | G113: =IF(数据!B123=0,"",数据!P123)
A114: =IF(数据!B124=0,"",数据!B124) | B114: =IF(数据!B124=0,"",数据!D124) | C114: =IF(数据!B124=0,"",数据!F124&"-"&数据!G124) | D114: =IF(数据!B124=0,"",数据!I124&数据!$I$1&数据!J124&数据!$J$1&数据!K124&数据!$K$1&数据!L124&数据!$L$1&数据!M124&数据!$M$1) | E114: =IF(数据!B124=0,"",数据!N124) | F114: =IF(数据!B124=0,"",数据!O124) | G114: =IF(数据!B124=0,"",数据!P124)
A115: =IF(数据!B125=0,"",数据!B125) | B115: =IF(数据!B125=0,"",数据!D125) | C115: =IF(数据!B125=0,"",数据!F125&"-"&数据!G125) | D115: =IF(数据!B125=0,"",数据!I125&数据!$I$1&数据!J125&数据!$J$1&数据!K125&数据!$K$1&数据!L125&数据!$L$1&数据!M125&数据!$M$1) | E115: =IF(数据!B125=0,"",数据!N125) | F115: =IF(数据!B125=0,"",数据!O125) | G115: =IF(数据!B125=0,"",数据!P125)
A116: =IF(数据!B126=0,"",数据!B126) | B116: =IF(数据!B126=0,"",数据!D126) | C116: =IF(数据!B126=0,"",数据!F126&"-"&数据!G126) | D116: =IF(数据!B126=0,"",数据!I126&数据!$I$1&数据!J126&数据!$J$1&数据!K126&数据!$K$1&数据!L126&数据!$L$1&数据!M126&数据!$M$1) | E116: =IF(数据!B126=0,"",数据!N126) | F116: =IF(数据!B126=0,"",数据!O126) | G116: =IF(数据!B126=0,"",数据!P126)
... A187: =IF(数据!B197=0,"",数据!B197) | B187: =IF(数据!B197=0,"",数据!D197) | C187: =IF(数据!B197=0,"",数据!F197&"-"&数据!G197) | D187: =IF(数据!B197=0,"",数据!I197&数据!$I$1&数据!J197&数据!$J$1&数据!K197&数据!$K$1&数据!L197&数据!$L$1&数据!M197&数据!$M$1) | E187: =IF(数据!B197=0,"",数据!N197) | F187: =IF(数据!B197=0,"",数据!O197) | G187: =IF(数据!B197=0,"",数据!P197)
A188: =IF(数据!B182=0,"",数据!B182) | B188: =IF(数据!B182=0,"",数据!D182) | C188: =IF(数据!B182=0,"",数据!F182&"-"&数据!G182) | D188: =IF(数据!B182=0,"",数据!I182&数据!$I$1&数据!J182&数据!$J$1&数据!K182&数据!$K$1&数据!L182&数据!$L$1&数据!M182&数据!$M$1) | E188: =IF(数据!B182=0,"",数据!N182) | F188: =IF(数据!B182=0,"",数据!O182) | G188: =IF(数据!B182=0,"",数据!P182)
A189: =IF(数据!B183=0,"",数据!B183) | B189: =IF(数据!B183=0,"",数据!D183) | C189: =IF(数据!B183=0,"",数据!F183&"-"&数据!G183) | D189: =IF(数据!B183=0,"",数据!I183&数据!$I$1&数据!J183&数据!$J$1&数据!K183&数据!$K$1&数据!L183&数据!$L$1&数据!M183&数据!$M$1) | E189: =IF(数据!B183=0,"",数据!N183) | F189: =IF(数据!B183=0,"",数据!O183) | G189: =IF(数据!B183=0,"",数据!P183)
A190: =IF(数据!B184=0,"",数据!B184) | B190: =IF(数据!B184=0,"",数据!D184) | C190: =IF(数据!B184=0,"",数据!F184&"-"&数据!G184) | D190: =IF(数据!B184=0,"",数据!I184&数据!$I$1&数据!J184&数据!$J$1&数据!K184&数据!$K$1&数据!L184&数据!$L$1&数据!M184&数据!$M$1) | E190: =IF(数据!B184=0,"",数据!N184) | F190: =IF(数据!B184=0,"",数据!O184) | G190: =IF(数据!B184=0,"",数据!P184)
A191: =IF(数据!B184=0,"",数据!B184) | B191: =IF(数据!B184=0,"",数据!D184) | C191: =IF(数据!B184=0,"",数据!F184&"-"&数据!G184) | D191: =IF(数据!B184=0,"",数据!I184&数据!$I$1&数据!J184&数据!$J$1&数据!K184&数据!$K$1&数据!L184&数据!$L$1&数据!M184&数据!$M$1) | E191: =IF(数据!B184=0,"",数据!N184) | F191: =IF(数据!B184=0,"",数据!O184) | G191: =IF(数据!B184=0,"",数据!P184)
A192: =IF(数据!B185=0,"",数据!B185) | B192: =IF(数据!B185=0,"",数据!D185) | C192: =IF(数据!B185=0,"",数据!F185&"-"&数据!G185) | D192: =IF(数据!B185=0,"",数据!I185&数据!$I$1&数据!J185&数据!$J$1&数据!K185&数据!$K$1&数据!L185&数据!$L$1&数据!M185&数据!$M$1) | E192: =IF(数据!B185=0,"",数据!N185) | F192: =IF(数据!B185=0,"",数据!O185) | G192: =IF(数据!B185=0,"",数据!P185)
A193: =IF(数据!B186=0,"",数据!B186) | B193: =IF(数据!B186=0,"",数据!D186) | C193: =IF(数据!B186=0,"",数据!F186&"-"&数据!G186) | D193: =IF(数据!B186=0,"",数据!I186&数据!$I$1&数据!J186&数据!$J$1&数据!K186&数据!$K$1&数据!L186&数据!$L$1&数据!M186&数据!$M$1) | E193: =IF(数据!B186=0,"",数据!N186) | F193: =IF(数据!B186=0,"",数据!O186) | G193: =IF(数据!B186=0,"",数据!P186)

Sheet 数据
A1: 打印日期 | B1: 名称 | C1: 型号 | D1: 距离(米) | E1: 接头数 | F1: 芯数开始 | G1: 芯数结束 | H1: 年月 | I1: 年 | J1: 月 | K1: 日 | L1: 时 | M1: 分 | N1: 波长 | O1: 平均衰耗 | P1: 是否成端 | Q1: 事件点 | R1: 事件距离 | S1: 事件芯数
A2: 2019-11-5 | B2: 马嘶工业园光交至正威华东基站 | C2: 24D | D2: 109.4 | F2: 1 | G2: =LEFT(C2,LEN(C2)-1) -> 24 | H2: =TEXT(RAND()*("2022/11/20"-"2022/11/11")+"2022/11/11","e/m/d") -> 2022/11/14 | I2: =YEAR(H2) -> 2022 | J2: =MONTH(H2) -> 11 | K2: =DAY(H2) -> 14 | L2: =ROUND(RAND()*(18-7)+7,0) -> 14 | M2: =INT(RAND()*55)+1 -> 51 | N2: 1550 | O2: 0.19 | P2: 是 | Q2: 0-0-0-0-0-0 | R2: 0-0-0-0-0-0
A3: 2019-11-5 | B3: 南浔世友地板基站至南浔新桥南堍光交 | C3: 24D | D3: 1171.4 | F3: 1 | G3: =LEFT(C3,LEN(C3)-1) -> 24 | H3: =TEXT(RAND()*("2022/11/20"-"2022/11/11")+"2022/11/11","e/m/d") -> 2022/11/15 | I3: =YEAR(H3) -> 2022 | J3: =MONTH(H3) -> 11 | K3: =DAY(H3) -> 15 | L3: =ROUND(RAND()*(18-7)+7,0) -> 8 | M3: =INT(RAND()*55)+1 -> 36 | N3: 1550 | O3: 0.19 | P3: 是 | Q3: 0-0-0-0-0-0 | R3: 0-0-0-0-0-0
A4: 2019-11-5 | B4: 方家港基站至浔织路浔北路光交 | C4: 24D | D4: 1354.1 | F4: 1 | G4: =LEFT(C4,LEN(C4)-1) -> 24 | H4: =TEXT(RAND()*("2022/11/20"-"2022/11/11")+"2022/11/11","e/m/d") -> 2022/11/13 | I4: =YEAR(H4) -> 2022 | J4: =MONTH(H4) -> 11 | K4: =DAY(H4) -> 13 | L4: =ROUND(RAND()*(18-7)+7,0) -> 12 | M4: =INT(RAND()*55)+1 -> 30 | N4: 1550 | O4: 0.19 | P4: 是 | Q4: 0-0-0-0-0-0 | R4: 0-0-0-0-0-0
A5: 2019-11-5 | B5: 朱家田新基站至铁塔菱湖南鱼鳌基站 | C5: 24D | D5: 1607.5 | F5: 1 | G5: =LEFT(C5,LEN(C5)-1) -> 24 | H5: =TEXT(RAND()*("2022/11/20"-"2022/11/11")+"2022/11/11","e/m/d") -> 2022/11/17 | I5: =YEAR(H5) -> 2022 | J5: =MONTH(H5) -> 11 | K5: =DAY(H5) -> 17 | L5: =ROUND(RAND()*(18-7)+7,0) -> 15 | M5: =INT(RAND()*55)+1 -> 20 | N5: 1550 | O5: 0.19 | P5: 是 | Q5: 0-0-0-0-0-0 | R5: 0-0-0-0-0-0
A6: 2019-11-5 | B6: 花林农兴村基站至练市乌林浜基站 | C6: 24D | D6: 1133.2 | F6: 1 | G6: =LEFT(C6,LEN(C6)-1) -> 24 | H6: =TEXT(RAND()*("2022/11/20"-"2022/11/11")+"2022/11/11","e/m/d") -> 2022/11/19 | I6: =YEAR(H6) -> 2022 | J6: =MONTH(H6) -> 11 | K6: =DAY(H6) -> 19 | L6: =ROUND(RAND()*(18-7)+7,0) -> 9 | M6: =INT(RAND()*55)+1 -> 44 | N6: 1550 | O6: 0.19 | P6: 是 | Q6: 0-0-0-0-0-0 | R6: 0-0-0-0-0-0
B7: 嘉业路南光交至开元名都度假区20幢楼顶搬迁基站 | C7: 24D | D7: 1017.9 | E7: 1 | F7: 1 | G7: =LEFT(C7,LEN(C7)-1) -> 24 | H7: =TEXT(RAND()*("2022/11/20"-"2022/11/11")+"2022/11/11","e/m/d") -> 2022/11/15 | I7: =YEAR(H7) -> 2022 | J7: =MONTH(H7) -> 11 | K7: =DAY(H7) -> 15 | L7: =ROUND(RAND()*(18-7)+7,0) -> 13 | M7: =INT(RAND()*55)+1 -> 11 | N7: 1550 | O7: 0.19 | P7: 是 | Q7: 0-0-0-0-0-0 | R7: 0-0-0-0-0-0
B8: 骏马木业基站至引下大象酒店地下室机房 | C8: 48D | D8: 1760.4 | E8: 2 | F8: 1 | G8: =LEFT(C8,LEN(C8)-1) -> 48 | H8: =TEXT(RAND()*("2022/11/20"-"2022/11/11")+"2022/11/11","e/m/d") -> 2022/11/12 | I8: =YEAR(H8) -> 2022 | J8: =MONTH(H8) -> 11 | K8: =DAY(H8) -> 12 | L8: =ROUND(RAND()*(18-7)+7,0) -> 16 | M8: =INT(RAND()*55)+1 -> 19 | N8: 1550 | O8: 0.19 | P8: 是 | Q8: 0-0-0-0-0-0 | R8: 0-0-0-0-0-0
B9: 菱湖竹墩岔口光交至菱湖前丘家苑基站 | C9: 24D | D9: 1460.5 | F9: 1 | G9: =LEFT(C9,LEN(C9)-1) -> 24 | H9: =TEXT(RAND()*("2022/11/20"-"2022/11/11")+"2022/11/11","e/m/d") -> 2022/11/17 | I9: =YEAR(H9) -> 2022 | J9: =MONTH(H9) -> 11 | K9: =DAY(H9) -> 17 | L9: =ROUND(RAND()*(18-7)+7,0) -> 8 | M9: =INT(RAND()*55)+1 -> 30 | N9: 1550 | O9: 0.19 | P9: 是 | Q9: 0-0-0-0-0-0 | R9: 0-0-0-0-0-0
B10: 和孚毛东港基站至湖盐公路星光农机北光交 | C10: 24D | D10: 2304.2 | E10: 3 | F10: 1 | G10: =LEFT(C10,LEN(C10)-1) -> 24 | H10: =TEXT(RAND()*("2022/11/20"-"2022/11/11")+"2022/11/11","e/m/d") -> 2022/11/14 | I10: =YEAR(H10) -> 2022 | J10: =MONTH(H10) -> 11 | K10: =DAY(H10) -> 14 | L10: =ROUND(RAND()*(18-7)+7,0) -> 16 | M10: =INT(RAND()*55)+1 -> 28 | N10: 1550 | O10: 0.19 | P10: 是 | Q10: 0-0-0-0-0-0 | R10: 0-0-0-0-0-0
B11: 江蒋漾新村基站至西城路年丰路光交 | C11: 24D | D11: 556.2 | F11: 1 | G11: =LEFT(C11,LEN(C11)-1) -> 24 | H11: =TEXT(RAND()*("2022/11/20"-"2022/11/11")+"2022/11/11","e/m/d") -> 2022/11/19 | I11: =YEAR(H11) -> 2022 | J11: =MONTH(H11) -> 11 | K11: =DAY(H11) -> 19 | L11: =ROUND(RAND()*(18-7)+7,0) -> 14 | M11: =INT(RAND()*55)+1 -> 28 | N11: 1550 | O11: 0.19 | P11: 是 | Q11: 0-0-0-0-0-0 | R11: 0-0-0-0-0-0
B12: 阳光大道与外环南路光交至玉麟府无线机房 | C12: 24D | D12: 214 | F12: 1 | G12: =LEFT(C12,LEN(C12)-1) -> 24 | H12: =TEXT(RAND()*("2022/11/20"-"2022/11/11")+"2022/11/11","e/m/d") -> 2022/11/16 | I12: =YEAR(H12) -> 2022 | J12: =MONTH(H12) -> 11 | K12: =DAY(H12) -> 16 | L12: =ROUND(RAND()*(18-7)+7,0) -> 13 | M12: =INT(RAND()*55)+1 -> 10 | N12: 1550 | O12: 0.19 | P12: 是 | Q12: 0-0-0-0-0-0 | R12: 0-0-0-0-0-0
B13: 玉麟府无线机房至玉麟府有线机房 | C13: 24D | D13: 38.5 | F13: 1 | G13: =LEFT(C13,LEN(C13)-1) -> 24 | H13: =TEXT(RAND()*("2022/11/20"-"2022/11/11")+"2022/11/11","e/m/d") -> 2022/11/18 | I13: =YEAR(H13) -> 2022 | J13: =MONTH(H13) -> 11 | K13: =DAY(H13) -> 18 | L13: =ROUND(RAND()*(18-7)+7,0) -> 10 | M13: =INT(RAND()*55)+1 -> 19 | N13: 1550 | O13: 0.19 | P13: 是 | Q13: 0-0-0-0-0-0 | R13: 0-0-0-0-0-0
B14: 风顺路新安路光交至铁塔孔雀城四期基站 | C14: 24D | D14: 405.2 | F14: 1 | G14: =LEFT(C14,LEN(C14)-1) -> 24 | H14: =TEXT(RAND()*("2022/11/20"-"2022/11/11")+"2022/11/11","e/m/d") -> 2022/11/15 | I14: =YEAR(H14) -> 2022 | J14: =MONTH(H14) -> 11 | K14: =DAY(H14) -> 15 | L14: =ROUND(RAND()*(18-7)+7,0) -> 14 | M14: =INT(RAND()*55)+1 -> 54 | N14: 1550 | O14: 0.19 | P14: 是 | Q14: 0-0-0-0-0-0 | R14: 0-0-0-0-0-0
B15: 蝶来大酒店地下室机房光交至蝶来大酒店A1幢B1F弱电间 | C15: 24D | D15: 240.1 | F15: 1 | G15: =LEFT(C15,LEN(C15)-1) -> 24 | H15: =TEXT(RAND()*("2022/11/20"-"2022/11/11")+"2022/11/11","e/m/d") -> 2022/11/12 | I15: =YEAR(H15) -> 2022 | J15: =MONTH(H15) -> 11 | K15: =DAY(H15) -> 12 | L15: =ROUND(RAND()*(18-7)+7,0) -> 12 | M15: =INT(RAND()*55)+1 -> 45 | N15: 1550 | O15: 0.19 | P15: 是 | Q15: 0-0-0-0-0-0 | R15: 0-0-0-0-0-0
B16: 蝶来大酒店A1幢B1F弱电间至蝶来大酒店A2幢B1F弱电间 | C16: 24D | D16: 241 | F16: 1 | G16: =LEFT(C16,LEN(C16)-1) -> 24 | H16: =TEXT(RAND()*("2022/11/20"-"2022/11/11")+"2022/11/11","e/m/d") -> 2022/11/15 | I16: =YEAR(H16) -> 2022 | J16: =MONTH(H16) -> 11 | K16: =DAY(H16) -> 15 | L16: =ROUND(RAND()*(18-7)+7,0) -> 12 | M16: =INT(RAND()*55)+1 -> 35 | N16: 1550 | O16: 0.19 | P16: 是 | Q16: 0-0-0-0-0-0 | R16: 0-0-0-0-0-0
B17: 蝶来大酒店A1幢B1F弱电间至蝶来大酒店A2幢15F弱电间 | C17: 24D | D17: 288 | F17: 1 | G17: =LEFT(C17,LEN(C17)-1) -> 24 | H17: =TEXT(RAND()*("2022/11/20"-"2022/11/11")+"2022/11/11","e/m/d") -> 2022/11/18 | I17: =YEAR(H17) -> 2022 | J17: =MONTH(H17) -> 11 | K17: =DAY(H17) -> 18 | L17: =ROUND(RAND()*(18-7)+7,0) -> 13 | M17: =INT(RAND()*55)+1 -> 2 | N17: 1550 | O17: 0.19 | P17: 是 | Q17: 0-0-0-0-0-0 | R17: 0-0-0-0-0-0
B18: 联谊路直港路光交至铁塔新安社区东基站 | C18: 24D | D18: 132.3 | F18: 1 | G18: =LEFT(C18,LEN(C18)-1) -> 24 | H18: =TEXT(RAND()*("2022/11/20"-"2022/11/11")+"2022/11/11","e/m/d") -> 2022/11/13 | I18: =YEAR(H18) -> 2022 | J18: =MONTH(H18) -> 11 | K18: =DAY(H18) -> 13 | L18: =ROUND(RAND()*(18-7)+7,0) -> 11 | M18: =INT(RAND()*55)+1 -> 29 | N18: 1550 | O18: 0.19 | P18: 是 | Q18: 0-0-0-0-0-0 | R18: 0-0-0-0-0-0
B19: 漾南新村光交至铁塔漾南C区8幢基站 | C19: 24D | D19: 1126.9 | F19: 1 | G19: =LEFT(C19,LEN(C19)-1) -> 24 | H19: =TEXT(RAND()*("2022/11/20"-"2022/11/11")+"2022/11/11","e/m/d") -> 2022/11/11 | I19: =YEAR(H19) -> 2022 | J19: =MONTH(H19) -> 11 | K19: =DAY(H19) -> 11 | L19: =ROUND(RAND()*(18-7)+7,0) -> 13 | M19: =INT(RAND()*55)+1 -> 14 | N19: 1550 | O19: 0.19 | P19: 是 | Q19: 0-0-0-0-0-0 | R19: 0-0-0-0-0-0
B20: 菱湖竹墩污水泵站至铁塔通途桥梁构件公司基站 | C20: 24D | D20: 1107.2 | E20: 1 | F20: 1 | G20: =LEFT(C20,LEN(C20)-1) -> 24 | H20: =TEXT(RAND()*("2022/11/20"-"2022/11/11")+"2022/11/11","e/m/d") -> 2022/11/19 | I20: =YEAR(H20) -> 2022 | J20: =MONTH(H20) -> 11 | K20: =DAY(H20) -> 19 | L20: =ROUND(RAND()*(18-7)+7,0) -> 15 | M20: =INT(RAND()*55)+1 -> 32 | N20: 1550 | O20: 0.19 | P20: 是 | Q20: 0-0-0-0-0-0 | R20: 0-0-0-0-0-0
B21: 章家角基站至千金北基站 | C21: 24D | D21: 2366.6 | E21: 2 | F21: 1 | G21: =LEFT(C21,LEN(C21)-1) -> 24 | H21: =TEXT(RAND()*("2022/11/20"-"2022/11/11")+"2022/11/11","e/m/d") -> 2022/11/11 | I21: =YEAR(H21) -> 2022 | J21: =MONTH(H21) -> 11 | K21: =DAY(H21) -> 11 | L21: =ROUND(RAND()*(18-7)+7,0) -> 12 | M21: =INT(RAND()*55)+1 -> 29 | N21: 1550 | O21: 0.19 | P21: 是 | Q21: 0-0-0-0-0-0 | R21: 0-0-0-0-0-0
B22: 年丰路南林路光交至山水大酒店地下室弱电间新建分纤箱 | C22: 24D | D22: 750.2 | E22: 1 | F22: 1 | G22: =LEFT(C22,LEN(C22)-1) -> 24 | H22: =TEXT(RAND()*("2022/11/20"-"2022/11/11")+"2022/11/11","e/m/d") -> 2022/11/17 | I22: =YEAR(H22) -> 2022 | J22: =MONTH(H22) -> 11 | K22: =DAY(H22) -> 17 | L22: =ROUND(RAND()*(18-7)+7,0) -> 9 | M22: =INT(RAND()*55)+1 -> 49 | N22: 1550 | O22: 0.19 | P22: 是 | Q22: 0-0-0-0-0-0 | R22: 0-0-0-0-0-0
B23: 李家河基站至浔北路浔织路光交 | C23: 24D | D23: 852.5 | F23: 1 | G23: =LEFT(C23,LEN(C23)-1) -> 24 | H23: =TEXT(RAND()*("2022/11/20"-"2022/11/11")+"2022/11/11","e/m/d") -> 2022/11/11 | I23: =YEAR(H23) -> 2022 | J23: =MONTH(H23) -> 11 | K23: =DAY(H23) -> 11 | L23: =ROUND(RAND()*(18-7)+7,0) -> 8 | M23: =INT(RAND()*55)+1 -> 7 | N23: 1550 | O23: 0.19 | P23: 是 | Q23: 0-0-0-0-0-0 | R23: 0-0-0-0-0-0
B24: 双林基站至维多利大道倪家滩光交 | C24: 24D | D24: 323.5 | F24: 1 | G24: =LEFT(C24,LEN(C24)-1) -> 24 | H24: =TEXT(RAND()*("2022/11/20"-"2022/11/11")+"2022/11/11","e/m/d") -> 2022/11/18 | I24: =YEAR(H24) -> 2022 | J24: =MONTH(H24) -> 11 | K24: =DAY(H24) -> 18 | L24: =ROUND(RAND()*(18-7)+7,0) -> 7 | M24: =INT(RAND()*55)+1 -> 49 | N24: 1550 | O24: 0.19 | P24: 是 | Q24: 0-0-0-0-0-0 | R24: 0-0-0-0-0-0
B25: 年丰路西城路光交至翘楚棠小区14栋地下室传输机房 | C25: 24D | D25: 991.6 | E25: 1 | F25: 1 | G25: =LEFT(C25,LEN(C25)-1) -> 24 | H25: =TEXT(RAND()*("2022/11/20"-"2022/11/11")+"2022/11/11","e/m/d") -> 2022/11/13 | I25: =YEAR(H25) -> 2022 | J25: =MONTH(H25) -> 11 | K25: =DAY(H25) -> 13 | L25: =ROUND(RAND()*(18-7)+7,0) -> 7 | M25: =INT(RAND()*55)+1 -> 27 | N25: 1550 | O25: 0.19 | P25: 是 | Q25: 0-0-0-0-0-0 | R25: 0-0-0-0-0-0
B26: 翘楚棠小区14栋地下室传输机房至翘楚棠小区地下室无线机房 | C26: 24D | D26: 16.1 | F26: 1 | G26: =LEFT(C26,LEN(C26)-1) -> 24 | H26: =TEXT(RAND()*("2022/11/20"-"2022/11/11")+"2022/11/11","e/m/d") -> 2022/11/12 | I26: =YEAR(H26) -> 2022 | J26: =MONTH(H26) -> 11 | K26: =DAY(H26) -> 12 | L26: =ROUND(RAND()*(18-7)+7,0) -> 17 | M26: =INT(RAND()*55)+1 -> 6 | N26: 1550 | O26: 0.19 | P26: 是 | Q26: 0-0-0-0-0-0 | R26: 0-0-0-0-0-0
B27: 风顺路人瑞路光交至嘉都广场有线机房 | C27: 24D | D27: 329.2 | F27: 1 | G27: =LEFT(C27,LEN(C27)-1) -> 24 | H27: =TEXT(RAND()*("2022/11/20"-"2022/11/11")+"2022/11/11","e/m/d") -> 2022/11/13 | I27: =YEAR(H27) -> 2022 | J27: =MONTH(H27) -> 11 | K27: =DAY(H27) -> 13 | L27: =ROUND(RAND()*(18-7)+7,0) -> 9 | M27: =INT(RAND()*55)+1 -> 18 | N27: 1550 | O27: 0.19 | P27: 是 | Q27: 0-0-0-0-0-0 | R27: 0-0-0-0-0-0
B28: 嘉都广场有线机房至嘉都广场无线机房 | C28: 24D | D28: 45.5 | F28: 1 | G28: =LEFT(C28,LEN(C28)-1) -> 24 | H28: =TEXT(RAND()*("2022/11/20"-"2022/11/11")+"2022/11/11","e/m/d") -> 2022/11/18 | I28: =YEAR(H28) -> 2022 | J28: =MONTH(H28) -> 11 | K28: =DAY(H28) -> 18 | L28: =ROUND(RAND()*(18-7)+7,0) -> 10 | M28: =INT(RAND()*55)+1 -> 53 | N28: 1550 | O28: 0.19 | P28: 是 | Q28: 0-0-0-0-0-0 | R28: 0-0-0-0-0-0
B29: 嘉都广场有线机房至嘉都广场5#楼9F | C29: 24D | D29: 235.7 | F29: 1 | G29: =LEFT(C29,LEN(C29)-1) -> 24 | H29: =TEXT(RAND()*("2022/11/20"-"2022/11/11")+"2022/11/11","e/m/d") -> 2022/11/18 | I29: =YEAR(H29) -> 2022 | J29: =MONTH(H29) -> 11 | K29: =DAY(H29) -> 18 | L29: =ROUND(RAND()*(18-7)+7,0) -> 14 | M29: =INT(RAND()*55)+1 -> 37 | N29: 1550 | O29: 0.19 | P29: 是 | Q29: 0-0-0-0-0-0 | R29: 0-0-0-0-0-0
B30: 嘉都广场有线机房至嘉都广场3#楼2F | C30: 24D | D30: 201.3 | F30: 1 | G30: =LEFT(C30,LEN(C30)-1) -> 24 | H30: =TEXT(RAND()*("2022/11/20"-"2022/11/11")+"2022/11/11","e/m/d") -> 2022/11/12 | I30: =YEAR(H30) -> 2022 | J30: =MONTH(H30) -> 11 | K30: =DAY(H30) -> 12 | L30: =ROUND(RAND()*(18-7)+7,0) -> 11 | M30: =INT(RAND()*55)+1 -> 20 | N30: 1550 | O30: 0.19 | P30: 是 | Q30: 0-0-0-0-0-0 | R30: 0-0-0-0-0-0
B31: 嘉都广场有线机房至嘉都广场2#楼6F | C31: 24D | D31: 210.7 | F31: 1 | G31: =LEFT(C31,LEN(C31)-1) -> 24 | H31: =TEXT(RAND()*("2022/11/20"-"2022/11/11")+"2022/11/11","e/m/d") -> 2022/11/14 | I31: =YEAR(H31) -> 2022 | J31: =MONTH(H31) -> 11 | K31: =DAY(H31) -> 14 | L31: =ROUND(RAND()*(18-7)+7,0) -> 9 | M31: =INT(RAND()*55)+1 -> 14 | N31: 1550 | O31: 0.19 | P31: 是 | Q31: 0-0-0-0-0-0 | R31: 0-0-0-0-0-0
B32: 嘉都广场有线机房至嘉都广场1#楼1F | C32: 24D | D32: 232.1 | F32: 1 | G32: =LEFT(C32,LEN(C32)-1) -> 24 | H32: =TEXT(RAND()*("2022/11/20"-"2022/11/11")+"2022/11/11","e/m/d") -> 2022/11/19 | I32: =YEAR(H32) -> 2022 | J32: =MONTH(H32) -> 11 | K32: =DAY(H32) -> 19 | L32: =ROUND(RAND()*(18-7)+7,0) -> 16 | M32: =INT(RAND()*55)+1 -> 25 | N32: 1550 | O32: 0.19 | P32: 是 | Q32: 0-0-0-0-0-0 | R32: 0-0-0-0-0-0
B33: 贝尚湾一期消控机房至贝尚湾一期7幢配电间 | C33: 24D | D33: 452.3 | F33: 1 | G33: =LEFT(C33,LEN(C33)-1) -> 24 | H33: =TEXT(RAND()*("2022/11/20"-"2022/11/11")+"2022/11/11","e/m/d") -> 2022/11/18 | I33: =YEAR(H33) -> 2022 | J33: =MONTH(H33) -> 11 | K33: =DAY(H33) -> 18 | L33: =ROUND(RAND()*(18-7)+7,0) -> 13 | M33: =INT(RAND()*55)+1 -> 30 | N33: 1550 | O33: 0.19 | P33: 是 | Q33: 0-0-0-0-0-0 | R33: 0-0-0-0-0-0
B34: 贝尚湾一期7幢配电间至贝尚湾一期3幢配电间 | C34: 24D | D34: 229.1 | F34: 1 | G34: =LEFT(C34,LEN(C34)-1) -> 24 | H34: =TEXT(RAND()*("2022/11/20"-"2022/11/11")+"2022/11/11","e/m/d") -> 2022/11/13 | I34: =YEAR(H34) -> 2022 | J34: =MONTH(H34) -> 11 | K34: =DAY(H34) -> 13 | L34: =ROUND(RAND()*(18-7)+7,0) -> 14 | M34: =INT(RAND()*55)+1 -> 2 | N34: 1550 | O34: 0.19 | P34: 是 | Q34: 0-0-0-0-0-0 | R34: 0-0-0-0-0-0
B35: 贝尚湾一期消控机房至贝尚湾一期12幢配电间 | C35: 24D | D35: 338.4 | F35: 1 | G35: =LEFT(C35,LEN(C35)-1) -> 24 | H35: =TEXT(RAND()*("2022/11/20"-"2022/11/11")+"2022/11/11","e/m/d") -> 2022/11/18 | I35: =YEAR(H35) -> 2022 | J35: =MONTH(H35) -> 11 | K35: =DAY(H35) -> 18 | L35: =ROUND(RAND()*(18-7)+7,0) -> 11 | M35: =INT(RAND()*55)+1 -> 29 | N35: 1550 | O35: 0.19 | P35: 是 | Q35: 0-0-0-0-0-0 | R35: 0-0-0-0-0-0
B36: 贝尚湾一期12幢配电间至贝尚湾一期26幢配电间 | C36: 24D | D36: 289.1 | F36: 1 | G36: =LEFT(C36,LEN(C36)-1) -> 24 | H36: =TEXT(RAND()*("2022/11/20"-"2022/11/11")+"2022/11/11","e/m/d") -> 2022/11/12 | I36: =YEAR(H36) -> 2022 | J36: =MONTH(H36) -> 11 | K36: =DAY(H36) -> 12 | L36: =ROUND(RAND()*(18-7)+7,0) -> 14 | M36: =INT(RAND()*55)+1 -> 6 | N36: 1550 | O36: 0.19 | P36: 是 | Q36: 0-0-0-0-0-0 | R36: 0-0-0-0-0-0
B37: 贝尚湾一期消控机房至贝尚湾一期综合楼-1F设备间 | C37: 24D | D37: 47 | F37: 1 | G37: =LEFT(C37,LEN(C37)-1) -> 24 | H37: =TEXT(RAND()*("2022/11/20"-"2022/11/11")+"2022/11/11","e/m/d") -> 2022/11/11 | I37: =YEAR(H37) -> 2022 | J37: =MONTH(H37) -> 11 | K37: =DAY(H37) -> 11 | L37: =ROUND(RAND()*(18-7)+7,0) -> 11 | M37: =INT(RAND()*55)+1 -> 34 | N37: 1550 | O37: 0.19 | P37: 是 | Q37: 0-0-0-0-0-0 | R37: 0-0-0-0-0-0
B38: 草船兜基站至直港新村59幢 | C38: 24D | D38: 2637.4 | E38: 1 | F38: 1 | G38: =LEFT(C38,LEN(C38)-1) -> 24 | H38: =TEXT(RAND()*("2022/11/20"-"2022/11/11")+"2022/11/11","e/m/d") -> 2022/11/16 | I38: =YEAR(H38) -> 2022 | J38: =MONTH(H38) -> 11 | K38: =DAY(H38) -> 16 | L38: =ROUND(RAND()*(18-7)+7,0) -> 11 | M38: =INT(RAND()*55)+1 -> 12 | N38: 1550 | O38: 0.19 | P38: 是 | Q38: 0-0-0-0-0-0 | R38: 0-0-0-0-0-0
B39: 直港新村59幢至直港新村88幢 | C39: 24D | D39: 438.7 | F39: 1 | G39: =LEFT(C39,LEN(C39)-1) -> 24 | H39: =TEXT(RAND()*("2022/11/20"-"2022/11/11")+"2022/11/11","e/m/d") -> 2022/11/15 | I39: =YEAR(H39) -> 2022 | J39: =MONTH(H39) -> 11 | K39: =DAY(H39) -> 15 | L39: =ROUND(RAND()*(18-7)+7,0) -> 9 | M39: =INT(RAND()*55)+1 -> 37 | N39: 1550 | O39: 0.19 | P39: 是 | Q39: 0-0-0-0-0-0 | R39: 0-0-0-0-0-0
B40: 直港新村59幢至直港新村30幢 | C40: 24D | D40: 472.6 | F40: 1 | G40: =LEFT(C40,LEN(C40)-1) -> 24 | H40: =TEXT(RAND()*("2022/11/20"-"2022/11/11")+"2022/11/11","e/m/d") -> 2022/11/13 | I40: =YEAR(H40) -> 2022 | J40: =MONTH(H40) -> 11 | K40: =DAY(H40) -> 13 | L40: =ROUND(RAND()*(18-7)+7,0) -> 11 | M40: =INT(RAND()*55)+1 -> 48 | N40: 1550 | O40: 0.19 | P40: 是 | Q40: 0-0-0-0-0-0 | R40: 0-0-0-0-0-0
...
